Workbook

Sheet План оплат
B2: 46121 | D2: Копилка б/н | E2: Б/н | F2: Нал | G2: Копилка нал | H2: факт нал | M2: Таблица заполняется до 10:00 Бухгалетерия/ Фин.служба
B3: Остатки на расчетных счетах | C3: 4778685 | D3: 200000 | E3: =C3+D3 | F3: 4358000 | H3: =F3+G3 | M3: Утверждается Управляющим Диреткором до 12:00
A4: =C3+H3+E4 | B4: План поступлений | E4: ='ДДС МЕСЯЦ'!V7+'ДДС МЕСЯЦ'!V8+'ДДС МЕСЯЦ'!V9+'ДДС МЕСЯЦ'!V12+'ДДС МЕСЯЦ'!V14+'ДДС МЕСЯЦ'!V18+'ДДС МЕСЯЦ'!V19 | F4: 0
A5: =E1131+E1132+E1133+E1134+E1135+E1136+E1137+F1131+F1132+F1133+F1134+F1135+F1136+F1137 | E5: план поступлений
B8: Дата | C8: Контрагент | D8: Назначение платежа | E8: Сумма Безнал. | F8: Сумма Нал. | G8: Сумма | H8: Статус | I8: Согласовано с Е.Е.
B9: 45813 | D9: Гугл диск | E9: 0 | F9: 30000 | G9: 30000 | H9: Отложено
B10: 45817 | C10: ИП Intellpack | D10: Ящики транспортировочные 100шт | E10: 419000 | F10: 0 | G10: 419000 | H10: Выплачено | M10: ЦЕНА ИЗМЕНИЛАСЬ
B11: 45818 | C11: Василий | D11: Ноутбук д/этикеровщика | E11: 0 | F11: 65000 | G11: 65000 | H11: Выплачено
B12: 45813 | D12: Закуп фруктов | E12: 0 | F12: 5465 | G12: 5465 | H12: Выплачено
B13: 45813 | D13: Форма силиконовая | E13: 0 | F13: 6400 | G13: 6400 | H13: Выплачено
B14: 45819 | D14: Миксер планетарный | E14: 270000 | G14: 270000 | H14: Отложено
B15: 45818 | C15: Расчет | D15: Уволенные сотрудники | E15: 0 | F15: 724000 | G15: 724000 | H15: Выплачено
B16: 45814 | D16: Вызывным катломойщицам | E16: 0 | F16: 24000 | G16: 24000 | H16: Выплачено
B17: 45814 | D17: ЗП Олеся | E17: 0 | F17: 2725000 | G17: 2725000 | H17: Выплачено
B18: 45783 | D18: Вызывные сотрудники | E18: 0 | F18: 120000 | G18: 120000 | H18: Выплачено
B19: 45817 | D19: Вернуть на кредитный счет | E19: 8000000 | F19: 0 | G19: 8000000 | H19: Выплачено
B20: 45817 | C20: Подотчет | D20: Бижанов Асылбек | E20: 0 | F20: 150000 | G20: 150000 | H20: Выплачено
B21: 45817 | C21: Отдел кадров | D21: Конц.товары и реклама | E21: 0 | F21: 25000 | G21: 25000 | H21: Отложено
B22: 45817 | D22: Принтер д/диспетчеров | E22: 272992 | F22: 0 | G22: 272992 | H22: Отложено
B23: 45817 | C23: Подотчет Есжановой Г | D23: Новый дизайн наклейки СЕГОДНЯ | E23: 0 | F23: 80000 | G23: 80000 | H23: Выплачено
B24: 45817 | D24: Гигрометр | E24: 150000 | F24: 0 | G24: 150000 | H24: Отложено
B25: 45817 | D25: Вызывные повара (пекарня,котломойка) | E25: 0 | F25: 87000 | G25: 87000 | H25: Выплачено
B26: 45817 | D26: Инвентарь | E26: 0 | F26: 740200 | G26: 740200 | H26: Отложено
B27: 45817 | C27: отложить | D27: на подключение ТП (шкаф, кабеля и тд) | E27: 2000000 | F27: 0 | G27: 2000000 | H27: Отложено
B28: 45818 | D28: ЗП Ковешниковой Зои | E28: 0 | F28: 1533571 | G28: 1533571 | H28: Выплачено
B29: 45818 | C29: на карточку сотрудникам | D29: Офицальное зп | E29: 13933776 | F29: 0 | G29: 13933776 | H29: Выплачено
B30: 45818 | C30: Подотчет | D30: Ли Станислав | E30: 0 | F30: 300000 | G30: 300000 | H30: Выплачено
B31: 45820 | C31: Вон С | D31: Инвентарь | E31: 0 | F31: 200000 | G31: 200000 | H31: Отложено
B32: 45818 | C32: Сон Сергей | D32: Штрих коды по курсу 6,45*8000 рубль | E32: 0 | F32: 51600 | G32: 51600 | H32: Выплачено
B33: 45818 | C33: Сырье | D33: Оплата по поставщикам | E33: 10434810 | F33: 0 | G33: 10434810 | H33: Выплачено
B34: 45819 | C34: Исполнительные листы | D34: ЧСИ по сотрудникам | E34: 573335 | F34: 0 | G34: 589785 | H34: Выплачено
B35: 45819 | C35: снимаем со счета | D35: на копилку 2 млн, на зп 2 млн | E35: 0 | F35: 4000000 | G35: 4000000 | H35: Выплачено
B36: 45819 | C36: Сырье | D36: Оплата по поставщикам (вторая часть) | E36: 8000000 | F36: 0 | G36: 9102655 | H36: Выплачено
B37: 45819 | D37: Стерилезатор | E37: 84800 | F37: 0 | G37: 84800 | H37: Выплачено
B38: 45819 | C38: Рынок | D38: Инвентарь д/кондитерки | E38: 0 | F38: 150000 | G38: 150000 | H38: Выплачено
B39: 45819 | D39: Светлана | F39: 140000 | G39: 140000 | H39: Выплачено
B40: 45819 | C40: Подотчет | D40: Ли Станислав | F40: 300000 | G40: 300000 | H40: Выплачено
B41: 45819 | C41: ч-з Арнур (на каспий ФЛ) | D41: Установка счетчика | F41: 220000 | G41: 220000 | H41: Выплачено
B42: 45819 | D42: Уволенные сотрудники | F42: 573014 | G42: 573014 | H42: Выплачено
B43: 45819 | C43: Подотчет | D43: Сон С | F43: 100000 | G43: 100000 | H43: Выплачено
...

Sheet Банки всех ТОО и ИП
A1: Контакт ведущего менеджера по банку (ИМЯ, телефон) | B1: Наименование ТОО/ИП | C1: Банк | D1: Подписант | E1: Механика подписания | F1: Владелец счёта | G1: Директор | H1: На кого есть доверенность | I1: Доступ Бух просмотра и выставления счетов | J1: Комментарии
A2: 2323 | B2: ТОО "Фуд завод" | C2: Каспи | D2: Ольга и Олеся | E2: on-line, приложение | F2: Эрик Цой | G2: Эрик Цой | H2: Олеся | I2: Бухгалтерия предприятия, открывает доступ Ольга | J2: снятие Акерке, создание платежей Я и Акерке
A3: Эльвира, 8-705-182-05-05 | B3: ТОО "Фуд завод" | C3: Жусан | D3: Ольга и Олеся | E3: on-line | F3: Эрик Цой | G3: Эрик Цой | H3: Олеся | I3: Бухгалтерия предприятия, открывает доступ Ольга | J3: создает платежки зарплатный бухгалтер через этот счет оплачивает исполнительный лист
A4: Лия, 8-775-133-21-96 | B4: ТОО "Фуд завод" | C4: РБК | D4: Ольга и Олеся | E4: on-line, через ОТП ключ, ключ у Акерке. Вход чепрез логин и пароль на сайт банка. эцп? | F4: Эрик Цой | G4: Эрик Цой | H4: Олеся | I4: Бухгалтерия предприятия, открывает доступ Ольга | J4: Акерке на создание и снятие через пароль и ключ ОТП
A5: риск | B5: ИП Айдана (ТОО "Фуд завод") | C5: Каспи | D5: Ольга и Олеся | E5: on-line | F5: Айдана | G5: Айдана | H5: Айдана и Акерке | I5: Бухгалтерия предприятия, открывает доступ Ольга | J5: создает Акерке
A6: риск | B6: ИП Сапакова (КБ) | C6: Каспи | D6: Айдана | E6: on-line | F6: Айгерим | H6: Айдана | J6: создает Акерке
A7: риск | B7: ИП Сапакова (КБ) | C7: Нур Банк | D7: Айдана | E7: on-line | F7: Айгерим | H7: Айдана | J7: ключи достпупа есть у нас в бухгалтерии вместе в ключом от подписи, может просматривать Юрий
A8: риск | B8: ТОО Армидейл | C8: Каспи | D8: Айдана+Акерке (до 01.06.26) | E8: on-line | F8: Армен | H8: Акерке, Айдана | J8: Акерке создает платежи и снимает деньги
A9: риск | B9: ТОО На районе Crave (Жетысу) | C9: Каспи | D9: Айдана | E9: on-line | F9: Артём | H9: Айдана, Акерке | J9: Акерке создает платежи и снимает деньги
B10: ТОО Кристалфрайз | C10: Каспи | D10: Ольга и Олеся | E10: on-line | F10: Малышев С | G10: Малышев С | H10: Ольга и Олеся | I10: Бухгалтерия предприятия, открывает доступ Ольга | J10: создает и подписывает Айгерим Сапакова
B11: ТОО "Фуд завод Астана" | C11: Каспий | D11: Олеся | E11: on-line | F11: Олеся Сергеевна | G11: Олеся Сергеевна | H11: -
B12: ТОО "Фуд завод Астана" | C12: БЦК | D12: Олеся | E12: on-line | F12: Олеся Сергеевна | G12: Олеся Сергеевна | H12: -
B13: ТОО "Фуд завод Астана" | C13: Форте | D13: Олеся | E13: on-line | F13: Олеся Сергеевна | G13: Олеся Сергеевна | H13: - | J13: надо организовтаь доступ к форте онлайн
B14: ТОО "Фуд завод Астана" | C14: Фридом | D14: Олеся

Sheet ДЕНЬ ОПЛАТ
B1: ПРОСТАВЬТЕ ДАТУ
B2: 46202 | C2: Остаток на начало | D2: Поступление | E2: Выбытие | F2: Остаток на конец | H2: Оплата поставщикам | N2: ОПИУ на 25.06.2026
B3: Расчётный счёт | C3: =12786388-C4-C5 | D3: =SUMIF(B11:B260,B2,E11:E260) | E3: =SUMIF(B265:B722,B2,E265:E722) | F3: =C3+D3-E3 | H3: 01.06-07.06.2026 | I3: 08.06-14.06.2026 | J3: 15.06-21.06.2026 | K3: 22.06-28.06.2026 | L3: 29.06-30.06.2027 | M3: сумма, средний %
B4: Касса | C4: 2008321 | D4: =SUMIF(B11:B262,B2,D10:D262) | E4: =SUMIF(B266:B723,B2,D266:D723) | F4: =C4+D4-E4 | G4: гашение КЗ | H4: =34458818+964000 | I4: =25257596+4303979+241995 | J4: =24398148+4556056 | K4: =27832950+2576580+718145 | L4: 1 | M4: =I4+J4+K4+L4+H4 | N4: 114121764
B5: Копилка | C5: 9800000 | G5: выручка | H5: 49606340 | I5: 72681513 | J5: 60988297 | K5: =45642381 | L5: 1 | M5: =I5+J5+K5+L5+H5 | N5: 231572946
B6: ИТОГО | C6: =C5+C4+C3 | D6: =D3+D4+D5 | E6: =E3+E4+E5 | F6: =F3+F4+F5 | G6: % от выручки | H6: =H4/H5 | I6: =I4/I5 | J6: =J4/J5 | K6: =K4/K5 | L6: =L4/L5 | M6: =AVERAGE(I6:L6) | N6: =N4/N5
K8: -28825915
B9: Поступления | K9: -2876580
B10: Дата | C10: Наименование контрагента | D10: Наличный | E10: Безналичный | F10: Комментарий | K10: -718145
B11: 46128 | C11: ДФЗ | E11: 2000000
B12: 46128 | C12: Яндекс | E12: 3964105
B13: 46128 | C13: Даркстор | E13: 1000000
B14: 46128 | C14: Фуд Вендинг | D14: 1500000
B15: 46128 | C15: RP | E15: 5000000
B16: 46128 | C16: Wolf | E16: =18644+27718
B17: 46128 | C17: Базилик | E17: 675750
B18: 46129 | C18: Crave | E18: 800000
B19: 46129 | C19: DQ | E19: 672552
B20: 46129 | C20: ДФЗ | E20: 5000000
B21: 46129 | C21: KASPI | E21: 1500000
B22: 46132 | C22: ДФЗ | E22: 11327800
B23: 46133 | C23: KASPI | E23: 900000
B24: 46133 | C24: ДФЗ | E24: 5305000
B25: 46133 | C25: Яндекс | E25: 7664529
B26: 46133 | C26: Базилик | E26: 979348
B27: 46134 | C27: Wolf | E27: 143759
B28: 46134 | C28: KASPI | E28: 1400000
... B31: 46135 | C31: ДФЗ | E31: 2530000
B32: 46135 | C32: Фуд Вендинг
B33: 46135 | C33: Wolf | E33: 29839
B34: 46135 | C34: Базилик | E34: 588058
B35: 46135 | C35: Бобух | E35: =337625+75706
B36: 46135 | C36: KASPI | E36: 1400000
B37: 46136 | C37: Алга | E37: 1000000
B38: 46136 | C38: ДФЗ | E38: 4880000
B39: 46136 | C39: KASPI | E39: 1500000
B40: 46136 | C40: Фуд Вендинг | D40: 1500000
B41: 46136 | C41: Бобух | E41: 84839
B42: 46136 | C42: Базилик | E42: 869592
B43: 46136 | C43: DSF | E43: 2000000
...

Sheet Неделя ОПЛАТ 
B1: ПРОСТАВЬТЕ неделю
B2: 1 | C2: Остаток на начало | D2: Поступление | E2: Выбытие | F2: Остаток на конец | H2: Оплата поставщикам | N2: ОПИУ на 25.06.2026
A3: 01.07.2026 (1нед, вкл. 29,30.26) | B3: Расчётный счёт | C3: 0 | D3: =SUMIF(B11:B121,B2,E11:E121) | E3: =SUMIF(B126:B447,B2,E126:E447) | F3: =C3+D3-E3 | H3: 01.06-07.06.2026 | I3: 08.06-14.06.2026 | J3: 15.06-21.06.2026 | K3: 22.06-28.06.2026 | L3: 29.06-30.06.2027 | M3: сумма, средний %
A4: 06.07.2026 (2нед) | B4: Касса | C4: 0 | D4: =SUMIF(B11:B123,B2,D10:D123) | E4: =SUMIF(B127:B448,B2,D127:D448) | F4: =C4+D4-E4 | G4: гашение КЗ | H4: =34458818+964000 | I4: =25257596+4303979+241995 | J4: =24398148+4556056 | K4: =27832950+2576580+718145 | L4: 1 | M4: =I4+J4+K4+L4+H4 | N4: 114121764
A5: 13.07.2026 (3нед) | B5: Копилка | C5: 0 | G5: выручка | H5: 49606340 | I5: 72681513 | J5: 60988297 | K5: =45642381 | L5: 1 | M5: =I5+J5+K5+L5+H5 | N5: 231572946
A6: 20.07.2026 (4 нед) | B6: ИТОГО | C6: =C5+C4+C3 | D6: =D3+D4+D5 | E6: =E3+E4+E5 | F6: =F3+F4+F5 | G6: % от выручки | H6: =H4/H5 | I6: =I4/I5 | J6: =J4/J5 | K6: =K4/K5 | L6: =L4/L5 | M6: =AVERAGE(I6:L6) | N6: =N4/N5
A7: 27.07.2026 (5 нед)
K8: -28825915
B9: Поступления | K9: -2876580
B10: Дата | C10: Наименование контрагента | D10: Наличный | E10: Безналичный | F10: Комментарий | K10: -718145
B11: 1 | C11: 85-ДФЗ (дистрибьютор) | E11: 22250000
B12: 1 | C12: 102-Яндекс лавка ОСНОВНОЙ | E12: 14000000
B13: 1 | C13: 7-Kaspi Банк (Склад ГП) | E13: 5000000
B14: 1 | C14: 99-RP АЗС основной | E14: 8000000
B15: 1 | C15: 96-ТОО DSF (дистрибьютор) | E15: 8000000
B16: 1 | C16: 2-Базилик 2 (Желтоксан) | E16: 1500000
B17: 1 | C17: 1-Базилик 1 (Шевченко) | E17: 1300000
B18: 1 | C18: 111 ТОО ГЛОВО ОСНОВНОЙ | E18: 1000000
B19: 1 | C19: 90-Маймарт | E19: 1000000
B20: 1 | C20: 0Частное лицо Покупатель | E20: 1000000
B21: 1 | C21: 110 АЗС "Sinooil" ШЫМКЕНТ | E21: 500000
B22: 1 | C22: 108-GO Market KRG ИП ОСНОВНОЙ | E22: 500000
... B82: 5 | C82: 558- ТРИО Romantic (торты) Нурлыбаев Алибек | E82: 260000
B124: Выбытие
B125: Дата | C125: Основание | D125: Наличный | E125: Безналичный | F125: Комментарий
B126: 46121 | C126: Бригадиру Болатбек Даулету | D126: 50000 | F126: Выплачено
B127: 46121 | C127: ЗП | E127: 15223109 | F127: Выплачено
B128: 46121 | C128: закуп сырьё | E128: 1776000 | F128: Выплачено
B129: 46121 | C129: ЗП лагманщикам | D129: 306000 | F129: Выплачено
B130: 46121 | C130: Ли Станислав | D130: 600000 | F130: Выплачено
B131: 46121 | C131: Дорожные | D131: 9000 | F131: Выплачено
B132: 46122 | C132: ОСТАТОК КПН | E132: 1104937 | F132: Выплачено
B133: 46122 | C133: ЗП Уволеных | D133: 2393824 | F133: Выплачено
B134: 46122 | C134: На размещение платных объявлений | D134: 20000 | F134: Выплачено
B135: 46122 | C135: Дизайнер РП (2 тейбл тента) | D135: 14000 | F135: Выплачено
B136: 46122 | C136: ЗП 5 сотрудникам они получает до 12 число | D136: 1251000 | F136: К оплате
B137: 46122 | C137: вызов ассенизаторской 2 машины | D137: 50000 | F137: Выплачено
B138: 46122 | C138: за оплату почты | D138: 107000 | F138: Выплачено
B139: 46122 | C139: Оплата за логистику Демьянов | D139: 300000 | F139: Выплачено
B140: 46122 | C140: Даулет, нач. производства ЗП | D140: 1281165 | F140: Выплачено
...

Sheet ДДС НЕДЕЛЬН.
C1: 46202 | D1: 46203 | E1: 46204 | F1: 46205 | G1: 46206 | H1: 1неделя | I1: 46209 | J1: 46210 | K1: 46211 | L1: 46212 | M1: 46213 | N1: 46216 | O1: 46217 | P1: 46218 | Q1: 46219 | R1: 46220 | S1: 46223 | T1: 46224 | U1: 46225 | V1: 46226 | W1: 46227 | X1: 46230 | Y1: 46231 | Z1: 46232 | AA1: 46233 | AB1: 46234
C2: понедельник | D2: вторник | E2: среда | F2: четверг | G2: пятница | I2: понедельник | J2: вторник | K2: среда | L2: четверг | M2: пятница | N2: понедельник | O2: вторник | P2: среда | Q2: четверг | R2: пятница | S2: понедельник | T2: вторник | U2: среда | V2: четверг | W2: пятница | X2: понедельник | Y2: вторник | Z2: среда | AA2: четверг | AB2: пятница | AC2: прирост 18% к факту апреля
C3: 46202 | D3: 46203 | E3: =E1 | F3: =F1 | G3: =G1 | I3: =I1 | J3: =J1 | K3: =K1 | L3: =L1 | M3: =M1 | N3: =N1 | O3: =O1 | P3: =P1 | ... AB3: =AB1 | AC3: Итого план | AD3: Итого факт | AE3: Отклонение
C4: План | D4: План | E4: План | F4: План | G4: План | I4: План | J4: План | K4: План | L4: План | M4: План | N4: План | O4: План | P4: План | Q4: План | R4: План | AA4: =Z80 | AB4: =AA80
A5: Остаток на начало по Банку | C5: 5000000 | D5: =C81 | E5: =D81 | F5: =E81 | G5: =F81 | H5: =G5 | I5: =G81 | J5: =I81 | K5: =J81 | L5: =K81 | M5: =L81 | N5: =M81 | O5: =N81 | P5: =O81 | Q5: =P81 | ... AB5: =AA81 | AC5: =#REF! | AD5: =AC5 | AE5: =AD5-AC5
A6: Остаток на начало по Кассе | C6: 5000000 | D6: =C82 | E6: =D82 | F6: =E82 | G6: =F82 | H6: =G6 | I6: =G82 | J6: =I82 | K6: =J82 | L6: =K82 | M6: =L82 | N6: =M82 | O6: =N82 | P6: =O82 | Q6: =P82 | ... AB6: =AA82 | AC6: =#REF! | AD6: =AC6 | AE6: =AD6-AC6
A7: Прочие | B7: Приход | C7: 1000000 | E7: 1000000 | G7: 1000000 | H7: =C7+D7+E7+F7+G7 | I7: 1000000 | K7: 1000000 | M7: 1000000 | N7: 1000000 | P7: 1000000 | R7: 1000000 | S7: 1000000 | U7: 1000000 | W7: 1000000 | X7: 1000000 | Z7: 1000000 | AA7: 1000000 | AC7: =C7+D7+E7+F7+G7+I7+J7+K7+L7+M7+N7+O7+P7+Q7+R7+S7+T7+U7+V7+W7+X7+Y7+Z7 | AD7: =#REF!+#REF!+#REF!+#REF!+#REF!+#REF!+#REF!+#REF!+#REF!+#REF!+#REF!+#REF!+#REF!+#REF!+#REF!+#REF!+#REF!+#REF!+#REF!+#REF!+#REF! | AE7: =AC7-AD7
A8: Б1, Б2, Б5 | B8: Приход | D8: 1000000 | E8: 1000000 | F8: 1000000 | G8: 1000000 | H8: =C8+D8+E8+F8+G8 | J8: 1000000 | L8: 1000000 | M8: 1000000 | O8: 1000000 | Q8: 1000000 | R8: 1000000 | T8: 1000000 | U8: 1000000 | V8: 1000000 | Y8: 1000000 | Z8: 1000000 | AA8: 10000000 | AC8: =C8+D8+E8+F8+G8+I8+J8+K8+L8+M8+N8+O8+P8+Q8+R8+S8+T8+U8+V8+W8+X8+Y8+Z8 | AD8: =#REF!+#REF!+#REF!+#REF!+#REF!+#REF!+#REF!+#REF!+#REF!+#REF!+#REF!+#REF!+#REF!+#REF!+#REF!+#REF!+#REF!+#REF!+#REF!+#REF!+#REF! | AE8: =AC8-AD8
A9: Яндекс | B9: Приход | D9: 6000000 | F9: 8000000 | H9: =C9+D9+E9+F9+G9 | J9: 6000000 | L9: 10000000 | O9: 6000000 | Q9: 10000000 | T9: 9000000 | V9: 10000000 | Y9: 9000000 | AA9: 2000000 | AC9: =C9+D9+E9+F9+G9+I9+J9+K9+L9+M9+N9+O9+P9+Q9+R9+S9+T9+U9+V9+W9+X9+Y9+Z9 | AD9: =#REF!+#REF!+#REF!+#REF!+#REF!+#REF!+#REF!+#REF!+#REF!+#REF!+#REF!+#REF!+#REF!+#REF!+#REF!+#REF!+#REF!+#REF!+#REF!+#REF!+#REF! | AE9: =AC9-AD9
A10: Май Март | B10: Приход | D10: 2000000 | F10: 2000000 | H10: =C10+D10+E10+F10+G10 | L10: 2000000 | Q10: 2000000 | T10: 2000000 | V10: 2000000 | Y10: 2000000 | AB10: 1000000 | AC10: =C10+D10+E10+F10+G10+I10+J10+K10+L10+M10+N10+O10+P10+Q10+R10+S10+T10+U10+V10+W10+X10+Y10+Z10 | AD10: =#REF!+#REF!+#REF!+#REF!+#REF!+#REF!+#REF!+#REF!+#REF!+#REF!+#REF!+#REF!+#REF!+#REF!+#REF!+#REF!+#REF!+#REF!+#REF!+#REF!+#REF! | AE10: =AC10-AD10
A11: 7-Kaspi Банк | B11: Приход | C11: 614000 | D11: 500000 | E11: 1000000 | F11: 1000000 | G11: 1000000 | H11: =C11+D11+E11+F11+G11 | I11: 1000000 | J11: 1000000 | K11: 1000000 | L11: 1000000 | M11: 1000000 | N11: 1000000 | O11: 1000000 | P11: 1000000 | Q11: 1000000 | R11: 1000000 | S11: 1000000 | U11: 1000000 | W11: 1000000 | X11: 1000000 | Z11: 1000000 | AB11: 3000000 | AC11: =C11+D11+E11+F11+G11+I11+J11+K11+L11+M11+N11+O11+P11+Q11+R11+S11+T11+U11+V11+W11+X11+Y11+Z11 | AD11: =#REF!+#REF!+#REF!+#REF!+#REF!+#REF!+#REF!+#REF!+#REF!+#REF!+#REF!+#REF!+#REF!+#REF!+#REF!+#REF!+#REF!+#REF!+#REF!+#REF!+#REF! | AE11: =AC11-AD11
A12: Crave | B12: Приход | D12: 200000 | H12: =C12+D12+E12+F12+G12 | I12: 3000000 | K12: 3000000 | M12: 3000000 | N12: 3000000 | P12: 3000000 | R12: 3000000 | S12: 3000000 | U12: 3000000 | W12: 3000000 | X12: 3000000 | Z12: 3000000 | AA12: 6000000 | AC12: =C12+D12+E12+F12+G12+I12+J12+K12+L12+M12+N12+O12+P12+Q12+R12+S12+T12+U12+V12+W12+X12+Y12+Z12 | AD12: =#REF!+#REF!+#REF!+#REF!+#REF!+#REF!+#REF!+#REF!+#REF!+#REF!+#REF!+#REF!+#REF!+#REF!+#REF!+#REF!+#REF!+#REF!+#REF!+#REF!+#REF! | AE12: =AC12-AD12
A13: 99-RP АЗС | B13: Приход | F13: 6000000 | H13: =C13+D13+E13+F13+G13 | L13: 6000000 | Q13: 6000000 | V13: 6000000 | AC13: =C13+D13+E13+F13+G13+I13+J13+K13+L13+M13+N13+O13+P13+Q13+R13+S13+T13+U13+V13+W13+X13+Y13+Z13 | AD13: =#REF!+#REF!+#REF!+#REF!+#REF!+#REF!+#REF!+#REF!+#REF!+#REF!+#REF!+#REF!+#REF!+#REF!+#REF!+#REF!+#REF!+#REF!+#REF!+#REF!+#REF! | AE13: =AC13-AD13
A14: 96- DSF покупатель | B14: Приход | D14: 4000000 | H14: =C14+D14+E14+F14+G14 | M14: 2000000 | Q14: 2000000 | U14: 1000000 | Z14: 1000000 | AA14: 4000000 | AB14: 4000000 | AC14: =C14+D14+E14+F14+G14+I14+J14+K14+L14+M14+N14+O14+P14+Q14+R14+S14+T14+U14+V14+W14+X14+Y14+Z14 | AD14: =#REF!+#REF!+#REF!+#REF!+#REF!+#REF!+#REF!+#REF!+#REF!+#REF!+#REF!+#REF!+#REF!+#REF!+#REF!+#REF!+#REF!+#REF!+#REF!+#REF!+#REF! | AE14: =AC14-AD14
A15: 85-ДФЗ дистрибьютер ФЗ | B15: Приход | C15: 11900000 | D15: 4000000 | F15: 4000000 | G15: 6000000 | H15: =C15+D15+E15+F15+G15 | I15: 2000000 | J15: 2000000 | K15: 10000000 | L15: 4000000 | M15: 2000000 | N15: 4000000 | O15: 1000000 | P15: 10000000 | Q15: 4000000 | R15: 2000000 | S15: 2000000 | T15: 5000000 | U15: 10000000 | V15: 4000000 | W15: 4000000 | X15: 2000000 | Y15: 5000000 | Z15: 10000000 | AC15: =C15+D15+E15+F15+G15+I15+J15+K15+L15+M15+N15+O15+P15+Q15+R15+S15+T15+U15+V15+W15+X15+Y15+Z15 | AD15: =#REF!+#REF!+#REF!+#REF!+#REF!+#REF!+#REF!+#REF!+#REF!+#REF!+#REF!+#REF!+#REF!+#REF!+#REF!+#REF!+#REF!+#REF!+#REF!+#REF!+#REF! | AE15: =AC15-AD15
A16: 110 АЗС №67 "Sinooil" | B16: Приход | D16: 200000 | F16: 150000 | H16: =C16+D16+E16+F16+G16 | J16: 1500000 | N16: 1000000 | U16: 2000000 | Z16: 2000000 | AC16: =C16+D16+E16+F16+G16+I16+J16+K16+L16+M16+N16+O16+P16+Q16+R16+S16+T16+U16+V16+W16+X16+Y16+Z16 | AD16: =#REF!+#REF!+#REF!+#REF!+#REF!+#REF!+#REF!+#REF!+#REF!+#REF!+#REF!+#REF!+#REF!+#REF!+#REF!+#REF!+#REF!+#REF!+#REF!+#REF!+#REF! | AE16: =AC16-AD16
A17: 100 ТУАР (шинлайн) | B17: Приход | H17: =C17+D17+E17+F17+G17 | AC17: =C17+D17+E17+F17+G17+I17+J17+K17+L17+M17+N17+O17+P17+Q17+R17+S17+T17+U17+V17+W17+X17+Y17+Z17 | AD17: =#REF!+#REF!+#REF!+#REF!+#REF!+#REF!+#REF!+#REF!+#REF!+#REF!+#REF!+#REF!+#REF!+#REF!+#REF!+#REF!+#REF!+#REF!+#REF!+#REF!+#REF! | AE17: =AC17-AD17
A18: Даркстор Чоко | B18: Приход | E18: 400000 | F18: 160000 | G18: 200000 | H18: =C18+D18+E18+F18+G18 | I18: 500000 | K18: 500000 | Q18: 650000 | S18: 150000 | U18: 150000 | X18: 150000 | Z18: 150000 | AA18: 200000 | AB18: 200000 | AC18: =C18+D18+E18+F18+G18+I18+J18+K18+L18+M18+N18+O18+P18+Q18+R18+S18+T18+U18+V18+W18+X18+Y18+Z18 | AD18: =#REF!+#REF!+#REF!+#REF!+#REF!+#REF!+#REF!+#REF!+#REF!+#REF!+#REF!+#REF!+#REF!+#REF!+#REF!+#REF!+#REF!+#REF!+#REF!+#REF!+#REF! | AE18: =AC18-AD18
A19: Глово, Вольт | B19: Приход | D19: 658000 | H19: =C19+D19+E19+F19+G19 | J19: 100000 | M19: 100000 | N19: 100000 | O19: 100000 | P19: 100000 | Q19: 100000 | R19: 100000 | S19: 200000 | T19: 100000 | U19: 200000 | V19: 200000 | W19: 200000 | X19: 200000 | Y19: 100000 | Z19: 200000 | AA19: 300000 | AC19: =C19+D19+E19+F19+G19+I19+J19+K19+L19+M19+N19+O19+P19+Q19+R19+S19+T19+U19+V19+W19+X19+Y19+Z19 | AD19: =#REF!+#REF!+#REF!+#REF!+#REF!+#REF!+#REF!+#REF!+#REF!+#REF!+#REF!+#REF!+#REF!+#REF!+#REF!+#REF!+#REF!+#REF!+#REF!+#REF!+#REF! | AE19: =AC19-AD19
A20: Торты | B20: Приход | C20: 65000 | D20: 20000 | F20: 109000 | H20: =C20+D20+E20+F20+G20 | Q20: 300000 | V20: 300000 | AA20: =SUM(AA6:AA19) | AB20: =SUM(AB6:AB19) | AC20: =C20+D20+E20+F20+G20+I20+J20+K20+L20+M20+N20+O20+P20+Q20+R20+S20+T20+U20+V20+W20+X20+Y20+Z20 | AD20: =#REF!+#REF!+#REF!+#REF!+#REF!+#REF!+#REF!+#REF!+#REF!+#REF!+#REF!+#REF!+#REF!+#REF!+#REF!+#REF!+#REF!+#REF!+#REF!+#REF!+#REF! | AE20: =AC20-AD20
A21: Итого по банку | B21: Приход | C21: =SUM(C7:C20) | D21: =SUM(D7:D20) | E21: =SUM(E7:E20) | F21: =SUM(F7:F20) | G21: =SUM(G7:G20) | H21: =SUM(H7:H20) | I21: =SUM(I7:I20) | J21: =SUM(J7:J20) | ... Z21: =SUM(Z7:Z20) | AC21: =C21+D21+E21+F21+G21+I21+J21+K21+L21+M21+N21+O21+P21+Q21+R21+S21+T21+U21+V21+W21+X21+Y21+Z21 | AD21: =#REF!+#REF!+#REF!+#REF!+#REF!+#REF!+#REF!+#REF!+#REF!+#REF!+#REF!+#REF!+#REF!+#REF!+#REF!+#REF!+#REF!+#REF!+#REF!+#REF!+#REF! | AE21: =AC21-AD21
A22: 97- Кейтеринг гость | B22: Приход | F22: 450000 | H22: =C22+D22+E22+F22+G22 | L22: 250000 | O22: 300000 | T22: 500000 | Y22: 500000 | AC22: =C22+D22+E22+F22+G22+I22+J22+K22+L22+M22+N22+O22+P22+Q22+R22+S22+T22+U22+V22+W22+X22+Y22+Z22 | AD22: =#REF!+#REF!+#REF!+#REF!+#REF!+#REF!+#REF!+#REF!+#REF!+#REF!+#REF!+#REF!+#REF!+#REF!+#REF!+#REF!+#REF!+#REF!+#REF!+#REF!+#REF! | AE22: =AC22-AD22
A23: Возврат с подотчета, Кредит | B23: Приход | H23: =C23+D23+E23+F23+G23 | AA23: 600000 | AC23: =C23+D23+E23+F23+G23+I23+J23+K23+L23+M23+N23+O23+P23+Q23+R23+S23+T23+U23+V23+W23+X23+Y23+Z23 | AD23: =#REF!+#REF!+#REF!+#REF!+#REF!+#REF!+#REF!+#REF!+#REF!+#REF!+#REF!+#REF!+#REF!+#REF!+#REF!+#REF!+#REF!+#REF!+#REF!+#REF!+#REF! | AE23: =AC23-AD23
A24: Crave | B24: Приход | C24: 600000 | F24: 600000 | H24: =C24+D24+E24+F24+G24 | I24: 600000 | L24: 600000 | N24: 600000 | Q24: 600000 | S24: 600000 | V24: 600000 | X24: 600000 | AA24: 1000000 | AC24: =C24+D24+E24+F24+G24+I24+J24+K24+L24+M24+N24+O24+P24+Q24+R24+S24+T24+U24+V24+W24+X24+Y24+Z24 | AD24: =#REF!+#REF!+#REF!+#REF!+#REF!+#REF!+#REF!+#REF!+#REF!+#REF!+#REF!+#REF!+#REF!+#REF!+#REF!+#REF!+#REF!+#REF!+#REF!+#REF!+#REF! | AE24: =AC24-AD24
A25: 7-Kaspi Банк (нал) | B25: Приход | F25: 1000000 | H25: =C25+D25+E25+F25+G25 | L25: 1000000 | Q25: 1000000 | V25: 1000000 | AC25: =C25+D25+E25+F25+G25+I25+J25+K25+L25+M25+N25+O25+P25+Q25+R25+S25+T25+U25+V25+W25+X25+Y25+Z25 | AD25: =#REF!+#REF!+#REF!+#REF!+#REF!+#REF!+#REF!+#REF!+#REF!+#REF!+#REF!+#REF!+#REF!+#REF!+#REF!+#REF!+#REF!+#REF!+#REF!+#REF!+#REF! | AE25: =AC25-AD25
A26: Частное лицо (Покупатель) | B26: Приход | F26: 200000 | H26: =C26+D26+E26+F26+G26 | L26: 400000 | Q26: 200000 | T26: 200000 | Y26: 200000 | AA26: 1500000 | AC26: =C26+D26+E26+F26+G26+I26+J26+K26+L26+M26+N26+O26+P26+Q26+R26+S26+T26+U26+V26+W26+X26+Y26+Z26 | AD26: =#REF!+#REF!+#REF!+#REF!+#REF!+#REF!+#REF!+#REF!+#REF!+#REF!+#REF!+#REF!+#REF!+#REF!+#REF!+#REF!+#REF!+#REF!+#REF!+#REF!+#REF! | AE26: =AC26-AD26
A27: 98-FOOD vending : СКЛАД АППАРАТ №1 (ФЗ Ермагамбет) | B27: Приход | F27: 1500000 | H27: =C27+D27+E27+F27+G27 | L27: 1500000 | Q27: 1500000 | V27: 1500000 | AA27: =SUM(AA21:AA26) | AB27: =SUM(AB21:AB26) | AC27: =C27+D27+E27+F27+G27+I27+J27+K27+L27+M27+N27+O27+P27+Q27+R27+S27+T27+U27+V27+W27+X27+Y27+Z27 | AD27: =#REF!+#REF!+#REF!+#REF!+#REF!+#REF!+#REF!+#REF!+#REF!+#REF!+#REF!+#REF!+#REF!+#REF!+#REF!+#REF!+#REF!+#REF!+#REF!+#REF!+#REF! | AE27: =AC27-AD27
A28: Итого по кассе | B28: Приход | C28: =SUM(C22:C27) | D28: =SUM(D22:D27) | E28: =SUM(E22:E27) | F28: =SUM(F22:F27) | G28: =SUM(G22:G27) | H28: =C28+D28+E28+F28+G28 | I28: =SUM(I22:I27) | J28: =SUM(J22:J27) | K28: =SUM(K22:K27) | L28: =SUM(L22:L27) | M28: =SUM(M22:M27) | N28: =SUM(N22:N27) | O28: =SUM(O22:O27) | P28: =SUM(P22:P27) | ... Z28: =SUM(Z22:Z27) | AA28: =AA20+AA27 | AB28: =AB20+AB27 | AC28: =C28+D28+E28+F28+G28+I28+J28+K28+L28+M28+N28+O28+P28+Q28+R28+S28+T28+U28+V28+W28+X28+Y28+Z28 | AD28: =#REF!+#REF!+#REF!+#REF!+#REF!+#REF!+#REF!+#REF!+#REF!+#REF!+#REF!+#REF!+#REF!+#REF!+#REF!+#REF!+#REF!+#REF!+#REF!+#REF!+#REF! | AE28: =AC28-AD28
A29: 1.Выручка | B29: Приход | C29: =C21+C28 | D29: =D21+D28 | E29: =E21+E28 | F29: =F21+F28 | G29: =G21+G28 | H29: =H21+H28 | I29: =I21+I28 | J29: =J21+J28 | ... Z29: =Z21+Z28 | AC29: =C29+D29+E29+F29+G29+I29+J29+K29+L29+M29+N29+O29+P29+Q29+R29+S29+T29+U29+V29+W29+X29+Y29+Z29 | AD29: =#REF!+#REF!+#REF!+#REF!+#REF!+#REF!+#REF!+#REF!+#REF!+#REF!+#REF!+#REF!+#REF!+#REF!+#REF!+#REF!+#REF!+#REF!+#REF!+#REF!+#REF! | AE29: =AC29-AD29
A30: IT-обслуживание,телефония,интернет | B30: Расход | D30: -90000 | F30: -220400 | H30: =C30+D30+E30+F30+G30 | S30: -90000 | T30: -90000 | X30: -90000 | Y30: -90000 | AC30: =C30+D30+E30+F30+G30+I30+J30+K30+L30+M30+N30+O30+P30+Q30+R30+S30+T30+U30+V30+W30+X30+Y30+Z30 | AD30: =#REF!+#REF!+#REF!+#REF!+#REF!+#REF!+#REF!+#REF!+#REF!+#REF!+#REF!+#REF!+#REF!+#REF!+#REF!+#REF!+#REF!+#REF!+#REF!+#REF!+#REF! | AE30: =AC30-AD30
A31: Авансы поставщикам | B31: Расход | H31: =C31+D31+E31+F31+G31 | AA31: -55000 | AB31: -55000 | AC31: =C31+D31+E31+F31+G31+I31+J31+K31+L31+M31+N31+O31+P31+Q31+R31+S31+T31+U31+V31+W31+X31+Y31+Z31 | AD31: =#REF!+#REF!+#REF!+#REF!+#REF!+#REF!+#REF!+#REF!+#REF!+#REF!+#REF!+#REF!+#REF!+#REF!+#REF!+#REF!+#REF!+#REF!+#REF!+#REF!+#REF! | AE31: =AC31-AD31
A32: Административные расходы | B32: Расход | C32: -55000 | D32: =-400000 | E32: -55000 | F32: -55000 | G32: -55000 | H32: =C32+D32+E32+F32+G32 | I32: -55000 | J32: -30000 | K32: -55000 | L32: -55000 | M32: -55000 | N32: -55000 | O32: -55000 | P32: -55000 | Q32: -55000 | R32: -55000 | S32: -55000 | T32: -55000 | U32: -55000 | V32: -55000 | W32: -55000 | X32: -55000 | Y32: -55000 | Z32: -55000 | AC32: =C32+D32+E32+F32+G32+I32+J32+K32+L32+M32+N32+O32+P32+Q32+R32+S32+T32+U32+V32+W32+X32+Y32+Z32 | AD32: =#REF!+#REF!+#REF!+#REF!+#REF!+#REF!+#REF!+#REF!+#REF!+#REF!+#REF!+#REF!+#REF!+#REF!+#REF!+#REF!+#REF!+#REF!+#REF!+#REF!+#REF! | AE32: =AC32-AD32
A33: Возврат ВФП | B33: Расход | H33: =C33+D33+E33+F33+G33 | AC33: =C33+D33+E33+F33+G33+I33+J33+K33+L33+M33+N33+O33+P33+Q33+R33+S33+T33+U33+V33+W33+X33+Y33+Z33 | AD33: =#REF!+#REF!+#REF!+#REF!+#REF!+#REF!+#REF!+#REF!+#REF!+#REF!+#REF!+#REF!+#REF!+#REF!+#REF!+#REF!+#REF!+#REF!+#REF!+#REF!+#REF! | AE33: =AC33-AD33
A34: Представительские расходы | B34: Расход | H34: =C34+D34+E34+F34+G34 | AC34: =C34+D34+E34+F34+G34+I34+J34+K34+L34+M34+N34+O34+P34+Q34+R34+S34+T34+U34+V34+W34+X34+Y34+Z34 | AD34: =#REF!+#REF!+#REF!+#REF!+#REF!+#REF!+#REF!+#REF!+#REF!+#REF!+#REF!+#REF!+#REF!+#REF!+#REF!+#REF!+#REF!+#REF!+#REF!+#REF!+#REF! | AE34: =AC34-AD34
A35: Аренда помещений | B35: Расход | H35: =C35+D35+E35+F35+G35 | J35: -6655000 | AC35: =C35+D35+E35+F35+G35+I35+J35+K35+L35+M35+N35+O35+P35+Q35+R35+S35+T35+U35+V35+W35+X35+Y35+Z35 | AD35: =#REF!+#REF!+#REF!+#REF!+#REF!+#REF!+#REF!+#REF!+#REF!+#REF!+#REF!+#REF!+#REF!+#REF!+#REF!+#REF!+#REF!+#REF!+#REF!+#REF!+#REF! | AE35: =AC35-AD35
A36: Газ | B36: Расход | H36: =C36+D36+E36+F36+G36 | S36: -630000 | X36: -630000 | AC36: =C36+D36+E36+F36+G36+I36+J36+K36+L36+M36+N36+O36+P36+Q36+R36+S36+T36+U36+V36+W36+X36+Y36+Z36 | AD36: =#REF!+#REF!+#REF!+#REF!+#REF!+#REF!+#REF!+#REF!+#REF!+#REF!+#REF!+#REF!+#REF!+#REF!+#REF!+#REF!+#REF!+#REF!+#REF!+#REF!+#REF! | AE36: =AC36-AD36
A37: Маркетинг | B37: Расход | H37: =C37+D37+E37+F37+G37 | AC37: =C37+D37+E37+F37+G37+I37+J37+K37+L37+M37+N37+O37+P37+Q37+R37+S37+T37+U37+V37+W37+X37+Y37+Z37 | AD37: =#REF!+#REF!+#REF!+#REF!+#REF!+#REF!+#REF!+#REF!+#REF!+#REF!+#REF!+#REF!+#REF!+#REF!+#REF!+#REF!+#REF!+#REF!+#REF!+#REF!+#REF! | AE37: =AC37-AD37
A38: Мусор | B38: Расход | H38: =C38+D38+E38+F38+G38 | M38: -100000 | Q38: -642920 | AC38: =C38+D38+E38+F38+G38+I38+J38+K38+L38+M38+N38+O38+P38+Q38+R38+S38+T38+U38+V38+W38+X38+Y38+Z38 | AD38: =#REF!+#REF!+#REF!+#REF!+#REF!+#REF!+#REF!+#REF!+#REF!+#REF!+#REF!+#REF!+#REF!+#REF!+#REF!+#REF!+#REF!+#REF!+#REF!+#REF!+#REF! | AE38: =AC38-AD38
A39: Налоги и другие платежи в бюджет | B39: Расход | H39: =C39+D39+E39+F39+G39 | M39: -8000000 | N39: -6000000 | T39: -12000000 | Y39: -12000000 | AC39: =C39+D39+E39+F39+G39+I39+J39+K39+L39+M39+N39+O39+P39+Q39+R39+S39+T39+U39+V39+W39+X39+Y39+Z39 | AD39: =#REF!+#REF!+#REF!+#REF!+#REF!+#REF!+#REF!+#REF!+#REF!+#REF!+#REF!+#REF!+#REF!+#REF!+#REF!+#REF!+#REF!+#REF!+#REF!+#REF!+#REF! | AE39: =AC39-AD39
A40: Оплата труда | B40: Расход | F40: -18500000 | H40: =C40+D40+E40+F40+G40 | Q40: -2030000 | AC40: =C40+D40+E40+F40+G40+I40+J40+K40+L40+M40+N40+O40+P40+Q40+R40+S40+T40+U40+V40+W40+X40+Y40+Z40 | AD40: =#REF!+#REF!+#REF!+#REF!+#REF!+#REF!+#REF!+#REF!+#REF!+#REF!+#REF!+#REF!+#REF!+#REF!+#REF!+#REF!+#REF!+#REF!+#REF!+#REF!+#REF! | AE40: =AC40-AD40
...

Sheet ВОЗВРАТ маймарт
B2: реализация | C2: возвраты | D2: %
A3: январь | B3: 11770526 | C3: 1232140 | D3: =C3/B3*100%
A4: февраль | B4: 14039988 | C4: 1973959 | D4: =C4/B4*100%
A5: март | B5: 15399728 | C5: 2054000 | D5: =C5/B5*100%
A6: апрель | B6: 21349838 | C6: 2168666 | D6: =C6/B6*100%

Sheet 3.3.5
A1: счёт 3.3.5 комиссия банка
A3: апрель | F3: Алгоритм: снятие по Фуд заводу, только через Жусан Банк. 5 000 000 через карту, 15 000 000 через Банк. Карту оставить в кассе, снимает Акерке. Олеся Сергеевна - 1 р. в месяц снимает деньги в банке. Любые переводы с Джусан банка (безналичные) под запретом. Остаток снимается с РБК.Уточнить есть ли карта в РБК!!!!!!!!!!!!!!!!!!!!!!!!!!!!!!!!!!! | H3: Пакет Comfort в РБК
A4: БАНК | B4: АПРЕЛЬ (тенге) | C4: май (тенге) | D4: вид платежа
A5: ФЗ РБК Каламкас | B5: 129175 | C5: =SUMIF($A$23:$A$35,A5,$R$23:$R$35) | D5: за перевод с РБК на каспи
A6: ФЗ Каспи | B6: 150470 | C6: =SUMIF($A$23:$A$35,A6,$R$23:$R$35) | D6: (комиссия за поступления торты, оплаты QR кодом)
A7: ФЗ Жусан Банк | B7: 27250 | C7: =SUMIF($A$23:$A$35,A7,$R$23:$R$35)
A8: ФЗ Айдана каспи | B8: 137150 | C8: =SUMIF($A$23:$A$35,A8,$R$23:$R$35)
A9: Касса Взаиморасчеты | B9: 156750 | C9: =SUMIF($A$23:$A$35,A9,$R$23:$R$35) | D9: обналичивание ИП Демьянов
A10: ИТОГО | B10: =B5+B6+B7+B8+B9 | C10: =C5+C6+C7+C8+C9
A13: Банк | B13: Комиссия за обналичивание | C13: Комиссия при снятии 10 млн ₸ | D13: Комиссия при снятии 50 млн ₸ | E13: Комментарий | F13: Лимит на снятие, мес без документов | G13: Лимит на снятие, с документами | H13: Корпоративная карточка | I13: Менеджер банка, тел
A14: Jusan Bank | B14: от 0,2% до 0,35% | C14: 20 000 – 30 000 ₸ (надо уточнить наши условия) | D14: 100 000 – 150 000 ₸ | E14: без заявки не принимают | F14: 5 на карту и 15 000 000 со счёта
A15: Bank RBK (COMFORT) | B15: от 0,2% до 0,55% | C15: 55 000 тенге по заявке, без заявки 77 000 тенге | D15: 100 000 – 225 000 ₸ | E15: принимают без заявки, % выше | F15: 10000000 | G15: 20000000
A16: Kaspi Business | B16: 0,95% сверх 1 млн ₸ | C16: 95 000 тенге | D16: 465 500 ₸ | E16: есть лимит - 4 млн./день
A17: Forte bank | B17: 0.006 | C17: 60 000 тенге | E17: лимит 10 млн. в день | F17: 20 000 000
C18: 9500 | D18: 4 | E18: =C18*D18
A19: Для регулярного снятия крупных сумм (от 10 млн ₸ и выше) наиболее выгодны Jusan Bank и Bank RBK. Kaspi удобен для расчетов и платежей, но менее выгоден для обналичивания крупных сумм.
A22: Счет/Банк | B22: январь 2025 | C22: февраль 2025 | D22: март 2025 | E22: апрель 2025 | F22: май 2025 | G22: июнь 2025 | H22: июль 2025 | I22: август 2025 | J22: сентябрь 2025 | K22: октябрь 2025 | L22: ноябрь 2025 | M22: декабрь 2025 | N22: январь 2026 | O22: февраль 2026 | P22: март 2026 | Q22: апрель 2026 | R22: май 2026 | S22: Итого
A23: ФЗ Каспи | B23: 21750 | C23: 31050 | D23: 233450 | E23: 242450 | F23: 232950 | G23: 496470 | H23: 261971 | I23: 435082 | J23: 248232 | K23: 465437 | L23: 381458 | M23: 231585 | N23: 177046 | O23: 55846 | P23: 121929 | Q23: 150470 | R23: 151441 | S23: 3938617
A24: ФЗ Ермагамбет отдел продаж | B24: 86623 | C24: 38050 | D24: 56803 | E24: 42800 | F24: 37100 | G24: 36245 | H24: 1950 | I24: 1950 | J24: 0 | K24: 1950 | L24: 0 | M24: 0 | N24: 0 | O24: 0 | P24: 0 | Q24: 0 | R24: 0 | S24: 303471
A25: ФЗ РБК Каламкас | B25: 89879 | C25: 101157 | D25: 56935 | E25: 28116 | F25: 134232 | G25: 78264 | H25: 78925 | I25: 75694 | J25: 132168 | K25: 100980 | L25: 76661 | M25: 58212 | N25: 62822 | O25: 61100 | P25: 49750 | Q25: 129175 | R25: 127040 | S25: 1441110
A26: ФЗ Жусан Банк | B26: 70670 | C26: 17855 | D26: 29239 | E26: 56322 | F26: 38050 | G26: 37300 | H26: 65500 | I26: 60200 | J26: 47400 | K26: 53750 | L26: 24187 | M26: 0 | N26: 17000 | O26: 8500 | P26: 8500 | Q26: 27250 | R26: 8500 | S26: 570223
A27: ФЗ Народный Банк (закр.) | B27: 0 | C27: 0 | D27: 15288 | E27: 0 | F27: 0 | G27: 0 | H27: 0 | I27: 0 | J27: 0 | K27: 0 | L27: 0 | M27: 0 | N27: 0 | O27: 0 | P27: 0 | Q27: 0 | R27: 0 | S27: 15288
A28: ФЗ ВТБ банк (закр.) | B28: 0 | C28: 0 | D28: 26948 | E28: 0 | F28: 0 | G28: 0 | H28: 0 | I28: 0 | J28: 0 | K28: 0 | L28: 0 | M28: 0 | N28: 0 | O28: 0 | P28: 0 | Q28: 0 | R28: 0 | S28: 26948
A29: Цой Д.Л.Каспи | B29: 0 | C29: 0 | D29: 0 | E29: 1290 | F29: 0 | G29: 0 | H29: 7600 | I29: 0 | J29: 0 | K29: 0 | L29: 0 | M29: 0 | N29: 0 | O29: 8859 | P29: 0 | Q29: 0 | R29: 0 | S29: 17749
A30: Алимова Каспи | B30: 0 | C30: 0 | D30: 0 | E30: 0 | F30: 0 | G30: 0 | H30: 0 | I30: 318 | J30: 0 | K30: 0 | L30: 0 | M30: 0 | N30: 0 | O30: 0 | P30: 0 | Q30: 0 | R30: 0 | S30: 318
A31: ФЗ РБК кредит | B31: 0 | C31: 0 | D31: 0 | E31: 0 | F31: 0 | G31: 0 | H31: 0 | I31: 0 | J31: 0 | K31: 0 | L31: 1000 | M31: 14500 | N31: 0 | O31: 0 | P31: 0 | Q31: 0 | R31: 0 | S31: 15500
A32: ФЗ Сапакова Кредит (Нурбанк) | B32: 0 | C32: 0 | D32: 0 | E32: 0 | F32: 0 | G32: 0 | H32: 0 | I32: 0 | J32: 0 | K32: 0 | L32: 0 | M32: 3450 | N32: 0 | O32: 5460 | P32: 3330 | Q32: 2400 | R32: 2400 | S32: 17040
A33: Касса Взаиморасчеты | B33: 0 | C33: 0 | D33: 0 | E33: 0 | F33: 0 | G33: 0 | H33: 0 | I33: 0 | J33: 0 | K33: 0 | L33: 0 | M33: 250230 | N33: 190000 | O33: 0 | P33: 38000 | Q33: 156750 | R33: 205200 | S33: 840180
A34: ФЗ Малышев каспи | B34: 0 | C34: 0 | D34: 0 | E34: 0 | F34: 0 | G34: 0 | H34: 0 | I34: 0 | J34: 0 | K34: 0 | L34: 0 | M34: 208985 | N34: 126900 | O34: 40000 | P34: 15000 | Q34: 0 | R34: 0 | S34: 390885
... A36: Итого | B36: 268922 | C36: 188112 | D36: 418663 | E36: 370978 | F36: 442332 | G36: 648279 | H36: 415946 | I36: 573244 | J36: 427800 | K36: 622117 | L36: 483306 | M36: 766962 | N36: 573768 | O36: 179765 | P36: 298309 | Q36: 603195 | R36: 676513 | S36: 7958211
B38: Банк
B39: РБК справки для снятия свыше 20 млн | C39: Описание
B40: 1. Справка по субъекту предпринимательства. | C40: справка подтверждающая, что у нас малый или средний бизнес, возможно с егов
B41: 2. Документы по источнику происхождения денежных средств. | C41: Договора с покупателями
B42: 3. Документы по целевому использованию. | C42: Письмо официальное, что мы закупаем за безналичный расчёт или выдаём зп налом
B44: Банк | C44: Наименование покупателя
B45: РБК | C45: 102-Яндекс лавка ОСНОВНОЙ
B46: РБК | C46: 103-Бобух ИП, ул. Торетай 92, бутик 103
B47: РБК | C47: 104-DQ12 ТОО г.Тараз, Конаева 12
B48: РБК | C48: 105-Алга экспресс ОСНОВНОЙ
...

Sheet Заявка ТМЦ
B1: Правило: все заявки поступающие в отдел снабжения до конца дня должны быть внесены в реестр, по мере согласования факта закупа перейти в лист День оплат, спланированы. Далее по факту отработки, пределаны инициатору
B5: Отработка ЗАЯВОК
B6: Дата поступления заявки | C6: Дата закупа | D6: Наименование товара | E6: Сумма | F6: ОТВЕТСТВЕННЫЙ | G6: Комментарий
B7: 46160 | C7: 46161 | D7: закуп в тех отдел Жансултан | E7: 456000 | F7: Александр | G7: Выполнено
C8: 46164 | D8: закуп | F8: Александр | G8: Закуп
B9: 46181 | D9: заявка дворник Владимир К. | E9: 30-50 тыс | F9: Жибек | G9: Закуп
A10: Asdecor | B10: 46182 | C10: 46197 | D10: в конд. цех коврики силиконовые 10 шт. | E10: 14900 | F10: Жибек | G10: Выполнено
A11: Horeca supplies | B11: 46182 | C11: 46203 | D11: блендер погружной Robot Coupe MINI MP190 V.V. 34750 1шт. | E11: 484000 | F11: Жибек | G11: Закуп
B12: 46182 | D12: овощорезка Китай | E12: 1200000 | F12: Александр | G12: Выполнено
A13: цена? | B13: 46188 | C13: 46195 | D13: сейф, для хранения документов А4 и печати | F13: Жибек | G13: Закуп
A14: Asdecor | B14: 46190 | C14: 46197 | D14: силиконовые лопатки 2 шт | E14: 1560 | F14: Жибек | G14: Выполнено
A15: Kaspi | B15: 46190 | C15: 46195 | D15: венчики маленькие 2 шт по 649 тг в каспи | E15: 1298 | F15: Жибек | G15: Закуп
A16: Kaspi | B16: 46190 | C16: 46195 | D16: сито для орешков 2 шт по 790 тг в каспи | E16: 1580 | F16: Жибек | G16: Закуп
B17: 46197 | D17: закуп расширительного бака на производство | E17: 95700 | F17: Александр | G17: Выполнено
A18: Химбаза | B18: 46199 | C18: 46204 | D18: промывалка с узким горлом для заполнения гигрометра | E18: 3500 | F18: Жибек | G18: Закуп
F19: Александр | G19: Закуп
F20: Александр | G20: Закуп
F21: Александр | G21: Закуп
F22: Александр | G22: Закуп
F23: Александр | G23: Закуп
F24: Александр | G24: Закуп
F25: Александр | G25: Закуп
F26: Александр | G26: Закуп
F27: Александр | G27: Закуп
F28: Александр | G28: Закуп
F29: Александр | G29: Закуп
F30: Александр | G30: Закуп
... F69: Александр | G69: Закуп

Sheet оборудование

Sheet ДДС МЕСЯЦ ИЮНЬ
K1: 46174 | M1: 46175 | O1: 46176 | Q1: 46177 | S1: 46178 | U1: 46181 | W1: 46182 | Y1: 46183 | AA1: 46184 | AC1: 46185 | AE1: 46188 | AG1: 46189 | AI1: 46190 | AK1: 46191 | AM1: 46192 | AO1: 46195 | AQ1: 46196 | AS1: 46197 | AU1: 46198 | AW1: 46199 | AY1: 46202 | BA1: 46203 | BC1: 46204
K2: понедельник | M2: вторник | O2: среда | Q2: четверг | S2: пятница | U2: понедельник | W2: вторник | Y2: среда | AA2: четверг | AC2: пятница | AE2: понедельник | AG2: вторник | AI2: среда | AK2: четверг | AM2: пятница | AO2: понедельник | AQ2: вторник | AS2: среда | AU2: четверг | AW2: пятница | AY2: понедельник | BA2: вторник | BC2: среда | BE2: прирост 18% к факту апреля
K3: 46174 | M3: 46175 | O3: 46176 | Q3: 46177 | S3: 46178 | U3: 46181 | W3: 46182 | Y3: 46183 | AA3: 46184 | AC3: 46185 | AE3: 46188 | AG3: 46189 | AI3: 46190 | AK3: 46191 | AM3: 46192 | AO3: 46195 | AQ3: 46196 | AS3: 46197 | AU3: 46198 | AW3: 46199 | AY3: 46202 | BA3: 46203 | BC3: 46204 | BE3: Итого план | BF3: Итого факт | BG3: Отклонение
C4: План | D4: Факт | E4: План | F4: Факт | G4: План | H4: Факт | I4: План | J4: Факт | K4: План | L4: Факт | M4: План | N4: Факт | O4: План | P4: Факт | Q4: План | R4: Факт | S4: План | T4: Факт | U4: План | V4: Факт | W4: План | X4: Факт | Y4: План | Z4: Факт | AA4: План | AB4: Факт | AC4: План | AD4: Факт | AE4: План | AF4: Факт | AG4: План | AH4: Факт | AI4: План | AJ4: Факт | AK4: План | AL4: Факт | AM4: План | AN4: Факт
A5: Остаток на начало по Банку | C5: 3140328 | D5: =C5 | E5: =C81 | F5: =D81 | G5: =E81 | H5: =3139916 | I5: =G81 | J5: =H81 | K5: 0 | L5: 0 | M5: =K81 | N5: =L81 | O5: =M81 | P5: =N81 | Q5: =O81 | R5: =P81 | S5: =Q81 | T5: =R81 | ... BD5: =BB81 | BE5: =C5 | BF5: =BE5 | BG5: =BF5-BE5
A6: Остаток на начало по Кассе | C6: 917728 | D6: =C6 | E6: =C82 | F6: =D82 | G6: =E82 | H6: =F82+62744 | I6: =G82 | J6: =H82 | K6: 0 | L6: 0 | M6: =K82 | N6: =L82 | O6: =M82 | P6: =N82 | Q6: =O82 | R6: =P82 | S6: =Q82 | T6: =R82 | ... BD6: =BB82 | BE6: =C6 | BF6: =BE6 | BG6: =BF6-BE6
A7: Прочие | B7: Приход | G7: 1000000 | K7: 1000000 | O7: 1000000 | S7: 1000000 | U7: 1000000 | Y7: 1000000 | AC7: 1000000 | AE7: 1000000 | AI7: 1000000 | AM7: 1000000 | AO7: 1000000 | AS7: 1000000 | AW7: 1000000 | AY7: 1000000 | BC7: 1000000 | BE7: =K7+M7+O7+Q7+S7+U7+W7+Y7+AA7+AC7+AE7+AG7+AI7+AK7+AM7+AO7+AQ7+AS7+AU7+AW7+AY7+BA7+BC7 | BF7: =#REF!+L7+N7+P7+R7+T7+V7+X7+Z7+AB7+AD7+AF7+AH7+AJ7+AL7+AN7+AP7+AR7+AT7+AV7+AX7 | BG7: =BE7-BF7
A8: Б1, Б2, Б5 | B8: Приход | M8: 1000000 | O8: 1000000 | Q8: 1000000 | S8: 1000000 | W8: 1000000 | AA8: 1000000 | AC8: 1000000 | AG8: 1000000 | AK8: 1000000 | AM8: 1000000 | AQ8: 1000000 | AS8: 1000000 | AU8: 1000000 | BA8: 1000000 | BC8: 1000000 | BE8: =K8+M8+O8+Q8+S8+U8+W8+Y8+AA8+AC8+AE8+AG8+AI8+AK8+AM8+AO8+AQ8+AS8+AU8+AW8+AY8+BA8+BC8 | BF8: =#REF!+L8+N8+P8+R8+T8+V8+X8+Z8+AB8+AD8+AF8+AH8+AJ8+AL8+AN8+AP8+AR8+AT8+AV8+AX8 | BG8: =BE8-BF8
A9: Яндекс | B9: Приход | I9: 6000000 | M9: 6000000 | Q9: 10000000 | W9: 6000000 | AA9: 10000000 | AG9: 6000000 | AK9: 10000000 | AQ9: 9000000 | AU9: 10000000 | BA9: 9000000 | BE9: =K9+M9+O9+Q9+S9+U9+W9+Y9+AA9+AC9+AE9+AG9+AI9+AK9+AM9+AO9+AQ9+AS9+AU9+AW9+AY9+BA9+BC9 | BF9: =#REF!+L9+N9+P9+R9+T9+V9+X9+Z9+AB9+AD9+AF9+AH9+AJ9+AL9+AN9+AP9+AR9+AT9+AV9+AX9 | BG9: =BE9-BF9
A10: Май Март | B10: Приход | G10: 1000000 | M10: 2000000 | Q10: 2000000 | AA10: 2000000 | AK10: 2000000 | AQ10: 2000000 | AU10: 2000000 | BA10: 2000000 | BE10: =K10+M10+O10+Q10+S10+U10+W10+Y10+AA10+AC10+AE10+AG10+AI10+AK10+AM10+AO10+AQ10+AS10+AU10+AW10+AY10+BA10+BC10 | BF10: =#REF!+L10+N10+P10+R10+T10+V10+X10+Z10+AB10+AD10+AF10+AH10+AJ10+AL10+AN10+AP10+AR10+AT10+AV10+AX10 | BG10: =BE10-BF10
A11: 7-Kaspi Банк | B11: Приход | G11: 1000000 | I11: 1500000 | O11: 1000000 | Q11: 1000000 | S11: 1000000 | U11: 1000000 | W11: 1000000 | Y11: 1000000 | AA11: 1000000 | AC11: 1000000 | AE11: 1000000 | AG11: 1000000 | AI11: 1000000 | AK11: 1000000 | AM11: 1000000 | AO11: 1000000 | AS11: 1000000 | AW11: 1000000 | AY11: 1000000 | BC11: 1000000 | BE11: =K11+M11+O11+Q11+S11+U11+W11+Y11+AA11+AC11+AE11+AG11+AI11+AK11+AM11+AO11+AQ11+AS11+AU11+AW11+AY11+BA11+BC11 | BF11: =#REF!+L11+N11+P11+R11+T11+V11+X11+Z11+AB11+AD11+AF11+AH11+AJ11+AL11+AN11+AP11+AR11+AT11+AV11+AX11 | BG11: =BE11-BF11
A12: Crave | B12: Приход | U12: 3000000 | Y12: 3000000 | AC12: 3000000 | AE12: 3000000 | AI12: 3000000 | AS12: 3000000 | AW12: 3000000 | AY12: 3000000 | BC12: 3000000 | BE12: =K12+M12+O12+Q12+S12+U12+W12+Y12+AA12+AC12+AE12+AG12+AI12+AK12+AM12+AO12+AQ12+AS12+AU12+AW12+AY12+BA12+BC12 | BF12: =#REF!+L12+N12+P12+R12+T12+V12+X12+Z12+AB12+AD12+AF12+AH12+AJ12+AL12+AN12+AP12+AR12+AT12+AV12+AX12 | BG12: =BE12-BF12
A13: 99-RP АЗС | B13: Приход | I13: 5000000 | Q13: 8000000 | AA13: 6000000 | AK13: 6000000 | AU13: 6000000 | BE13: =K13+M13+O13+Q13+S13+U13+W13+Y13+AA13+AC13+AE13+AG13+AI13+AK13+AM13+AO13+AQ13+AS13+AU13+AW13+AY13+BA13+BC13 | BF13: =#REF!+L13+N13+P13+R13+T13+V13+X13+Z13+AB13+AD13+AF13+AH13+AJ13+AL13+AN13+AP13+AR13+AT13+AV13+AX13 | BG13: =BE13-BF13
A14: 96- DSF покупатель | B14: Приход | G14: 5000000 | M14: 4000000 | AC14: 2000000 | AK14: 2000000 | AS14: 1000000 | BC14: 1000000 | BE14: =K14+M14+O14+Q14+S14+U14+W14+Y14+AA14+AC14+AE14+AG14+AI14+AK14+AM14+AO14+AQ14+AS14+AU14+AW14+AY14+BA14+BC14 | BF14: =#REF!+L14+N14+P14+R14+T14+V14+X14+Z14+AB14+AD14+AF14+AH14+AJ14+AL14+AN14+AP14+AR14+AT14+AV14+AX14 | BG14: =BE14-BF14
A15: 85-ДФЗ дистрибьютер ФЗ | B15: Приход | G15: 2000000 | I15: 2200000 | K15: 11900000 | M15: 4000000 | O15: 10000000 | Q15: 4000000 | S15: 2000000 | U15: 2000000 | W15: 2000000 | Y15: 10000000 | AA15: 4000000 | AC15: 2000000 | AE15: 4000000 | AG15: 1000000 | AI15: 10000000 | AK15: 4000000 | AM15: 2000000 | AO15: 2000000 | AQ15: 5000000 | AS15: 10000000 | AU15: 4000000 | AW15: 4000000 | AY15: 2000000 | BA15: 5000000 | BC15: 10000000 | BE15: =K15+M15+O15+Q15+S15+U15+W15+Y15+AA15+AC15+AE15+AG15+AI15+AK15+AM15+AO15+AQ15+AS15+AU15+AW15+AY15+BA15+BC15 | BF15: =#REF!+L15+N15+P15+R15+T15+V15+X15+Z15+AB15+AD15+AF15+AH15+AJ15+AL15+AN15+AP15+AR15+AT15+AV15+AX15 | BG15: =BE15-BF15
A16: 110 АЗС №67 "Sinooil" | B16: Приход | S16: 1000000 | W16: 1500000 | AE16: 1000000 | AS16: 2000000 | BC16: 2000000 | BE16: =K16+M16+O16+Q16+S16+U16+W16+Y16+AA16+AC16+AE16+AG16+AI16+AK16+AM16+AO16+AQ16+AS16+AU16+AW16+AY16+BA16+BC16 | BF16: =#REF!+L16+N16+P16+R16+T16+V16+X16+Z16+AB16+AD16+AF16+AH16+AJ16+AL16+AN16+AP16+AR16+AT16+AV16+AX16 | BG16: =BE16-BF16
A17: 100 ТУАР (шинлайн) | B17: Приход | G17: 150000 | BE17: =K17+M17+O17+Q17+S17+U17+W17+Y17+AA17+AC17+AE17+AG17+AI17+AK17+AM17+AO17+AQ17+AS17+AU17+AW17+AY17+BA17+BC17 | BF17: =#REF!+L17+N17+P17+R17+T17+V17+X17+Z17+AB17+AD17+AF17+AH17+AJ17+AL17+AN17+AP17+AR17+AT17+AV17+AX17 | BG17: =BE17-BF17
A18: Даркстор Чоко | B18: Приход | M18: 600000 | U18: 500000 | Y18: 500000 | AK18: 650000 | AO18: 150000 | AS18: 150000 | AY18: 150000 | BC18: 150000 | BE18: =K18+M18+O18+Q18+S18+U18+W18+Y18+AA18+AC18+AE18+AG18+AI18+AK18+AM18+AO18+AQ18+AS18+AU18+AW18+AY18+BA18+BC18 | BF18: =#REF!+L18+N18+P18+R18+T18+V18+X18+Z18+AB18+AD18+AF18+AH18+AJ18+AL18+AN18+AP18+AR18+AT18+AV18+AX18 | BG18: =BE18-BF18
A19: Глово, Вольт | B19: Приход | K19: 100000 | O19: 200000 | Q19: 200000 | S19: 100000 | W19: 100000 | AC19: 100000 | AE19: 100000 | AG19: 100000 | AI19: 100000 | AK19: 100000 | AM19: 100000 | AO19: 200000 | AQ19: 100000 | AS19: 200000 | AU19: 200000 | AW19: 200000 | AY19: 200000 | BA19: 100000 | BC19: 200000 | BE19: =K19+M19+O19+Q19+S19+U19+W19+Y19+AA19+AC19+AE19+AG19+AI19+AK19+AM19+AO19+AQ19+AS19+AU19+AW19+AY19+BA19+BC19 | BF19: =#REF!+L19+N19+P19+R19+T19+V19+X19+Z19+AB19+AD19+AF19+AH19+AJ19+AL19+AN19+AP19+AR19+AT19+AV19+AX19 | BG19: =BE19-BF19
A20: Торты | B20: Приход | Q20: 500000 | AK20: 300000 | AU20: 300000 | BE20: =K20+M20+O20+Q20+S20+U20+W20+Y20+AA20+AC20+AE20+AG20+AI20+AK20+AM20+AO20+AQ20+AS20+AU20+AW20+AY20+BA20+BC20 | BF20: =#REF!+L20+N20+P20+R20+T20+V20+X20+Z20+AB20+AD20+AF20+AH20+AJ20+AL20+AN20+AP20+AR20+AT20+AV20+AX20 | BG20: =BE20-BF20
A21: Итого по банку | B21: Приход | C21: 0 | D21: =SUM(D7:D20) | E21: =SUM(E7:E20) | F21: =SUM(F7:F20) | G21: =SUM(G7:G20) | H21: =SUM(H7:H20) | I21: =SUM(I7:I20) | J21: =SUM(J7:J20) | K21: =SUM(K7:K20) | ... BD21: =SUM(BD7:BD20) | BE21: =K21+M21+O21+Q21+S21+U21+W21+Y21+AA21+AC21+AE21+AG21+AI21+AK21+AM21+AO21+AQ21+AS21+AU21+AW21+AY21+BA21+BC21 | BF21: =#REF!+L21+N21+P21+R21+T21+V21+X21+Z21+AB21+AD21+AF21+AH21+AJ21+AL21+AN21+AP21+AR21+AT21+AV21+AX21 | BG21: =BE21-BF21
A22: 97- Кейтеринг гость | B22: Приход | Q22: 450000 | AA22: 250000 | AG22: 300000 | AQ22: 500000 | BA22: 500000 | BE22: =K22+M22+O22+Q22+S22+U22+W22+Y22+AA22+AC22+AE22+AG22+AI22+AK22+AM22+AO22+AQ22+AS22+AU22+AW22+AY22+BA22+BC22 | BF22: =#REF!+L22+N22+P22+R22+T22+V22+X22+Z22+AB22+AD22+AF22+AH22+AJ22+AL22+AN22+AP22+AR22+AT22+AV22+AX22 | BG22: =BE22-BF22
A23: Возврат с подотчета, Кредит | B23: Приход | H23: 40000 | BE23: =K23+M23+O23+Q23+S23+U23+W23+Y23+AA23+AC23+AE23+AG23+AI23+AK23+AM23+AO23+AQ23+AS23+AU23+AW23+AY23+BA23+BC23 | BF23: =#REF!+L23+N23+P23+R23+T23+V23+X23+Z23+AB23+AD23+AF23+AH23+AJ23+AL23+AN23+AP23+AR23+AT23+AV23+AX23 | BG23: =BE23-BF23
A24: Crave | B24: Приход | J24: 600000 | K24: 600000 | Q24: 600000 | U24: 600000 | AA24: 600000 | AE24: 600000 | AK24: 600000 | AO24: 600000 | AU24: 600000 | AY24: 600000 | BE24: =K24+M24+O24+Q24+S24+U24+W24+Y24+AA24+AC24+AE24+AG24+AI24+AK24+AM24+AO24+AQ24+AS24+AU24+AW24+AY24+BA24+BC24 | BF24: =#REF!+L24+N24+P24+R24+T24+V24+X24+Z24+AB24+AD24+AF24+AH24+AJ24+AL24+AN24+AP24+AR24+AT24+AV24+AX24 | BG24: =BE24-BF24
A25: 7-Kaspi Банк (нал) | B25: Приход | Q25: 1000000 | AA25: 1000000 | AK25: 1000000 | AU25: 1000000 | BE25: =K25+M25+O25+Q25+S25+U25+W25+Y25+AA25+AC25+AE25+AG25+AI25+AK25+AM25+AO25+AQ25+AS25+AU25+AW25+AY25+BA25+BC25 | BF25: =#REF!+L25+N25+P25+R25+T25+V25+X25+Z25+AB25+AD25+AF25+AH25+AJ25+AL25+AN25+AP25+AR25+AT25+AV25+AX25 | BG25: =BE25-BF25
A26: Частное лицо (Покупатель) | B26: Приход | Q26: 200000 | AA26: 400000 | AK26: 200000 | AQ26: 200000 | BA26: 200000 | BE26: =K26+M26+O26+Q26+S26+U26+W26+Y26+AA26+AC26+AE26+AG26+AI26+AK26+AM26+AO26+AQ26+AS26+AU26+AW26+AY26+BA26+BC26 | BF26: =#REF!+L26+N26+P26+R26+T26+V26+X26+Z26+AB26+AD26+AF26+AH26+AJ26+AL26+AN26+AP26+AR26+AT26+AV26+AX26 | BG26: =BE26-BF26
A27: 98-FOOD vending : СКЛАД АППАРАТ №1 (ФЗ Ермагамбет) | B27: Приход | Q27: 1500000 | AA27: 1500000 | AK27: 1500000 | AU27: 1500000 | BE27: =K27+M27+O27+Q27+S27+U27+W27+Y27+AA27+AC27+AE27+AG27+AI27+AK27+AM27+AO27+AQ27+AS27+AU27+AW27+AY27+BA27+BC27 | BF27: =#REF!+L27+N27+P27+R27+T27+V27+X27+Z27+AB27+AD27+AF27+AH27+AJ27+AL27+AN27+AP27+AR27+AT27+AV27+AX27 | BG27: =BE27-BF27
A28: Итого по кассе | B28: Приход | C28: 0 | D28: =SUM(D22:D27) | E28: =SUM(E22:E27) | F28: =SUM(F22:F27) | G28: =SUM(G22:G27) | H28: =SUM(H22:H27) | I28: =SUM(I22:I27) | J28: =SUM(J22:J27) | K28: =SUM(K22:K27) | ... BD28: =SUM(BD22:BD27) | BE28: =K28+M28+O28+Q28+S28+U28+W28+Y28+AA28+AC28+AE28+AG28+AI28+AK28+AM28+AO28+AQ28+AS28+AU28+AW28+AY28+BA28+BC28 | BF28: =#REF!+L28+N28+P28+R28+T28+V28+X28+Z28+AB28+AD28+AF28+AH28+AJ28+AL28+AN28+AP28+AR28+AT28+AV28+AX28 | BG28: =BE28-BF28
A29: 1.Выручка | B29: Приход | C29: 0 | D29: =D21+D28 | E29: =E21+E28 | F29: =F21+F28 | G29: =G21+G28 | H29: =H21+H28 | I29: =I21+I28 | J29: =J21+J28 | K29: =K21+K28 | ... BD29: =BD21+BD28 | BE29: =K29+M29+O29+Q29+S29+U29+W29+Y29+AA29+AC29+AE29+AG29+AI29+AK29+AM29+AO29+AQ29+AS29+AU29+AW29+AY29+BA29+BC29 | BF29: =#REF!+L29+N29+P29+R29+T29+V29+X29+Z29+AB29+AD29+AF29+AH29+AJ29+AL29+AN29+AP29+AR29+AT29+AV29+AX29 | BG29: =BE29-BF29
A30: IT-обслуживание,телефония,интернет | B30: Расход | G30: -82240 | H30: =-85400-85177 | I30: -220400 | M30: -90000 | Q30: -220400 | AO30: -90000 | AQ30: -90000 | AY30: -90000 | BA30: -90000 | BE30: =K30+M30+O30+Q30+S30+U30+W30+Y30+AA30+AC30+AE30+AG30+AI30+AK30+AM30+AO30+AQ30+AS30+AU30+AW30+AY30+BA30+BC30 | BF30: =#REF!+L30+N30+P30+R30+T30+V30+X30+Z30+AB30+AD30+AF30+AH30+AJ30+AL30+AN30+AP30+AR30+AT30+AV30+AX30 | BG30: =BE30-BF30
A31: Авансы поставщикам | B31: Расход | BE31: =K31+M31+O31+Q31+S31+U31+W31+Y31+AA31+AC31+AE31+AG31+AI31+AK31+AM31+AO31+AQ31+AS31+AU31+AW31+AY31+BA31+BC31 | BF31: =#REF!+L31+N31+P31+R31+T31+V31+X31+Z31+AB31+AD31+AF31+AH31+AJ31+AL31+AN31+AP31+AR31+AT31+AV31+AX31 | BG31: =BE31-BF31
A32: Административные расходы | B32: Расход | H32: =-4000-1950 | I32: -3000 | J32: -6050 | K32: -55000 | M32: =-400000 | O32: -55000 | Q32: -55000 | S32: -55000 | U32: -55000 | W32: -30000 | Y32: -55000 | AA32: -55000 | AC32: -55000 | AE32: -55000 | AG32: -55000 | AI32: -55000 | AK32: -55000 | AM32: -55000 | AO32: -55000 | AQ32: -55000 | AS32: -55000 | AU32: -55000 | AW32: -55000 | AY32: -55000 | BA32: -55000 | BC32: -55000 | BE32: =K32+M32+O32+Q32+S32+U32+W32+Y32+AA32+AC32+AE32+AG32+AI32+AK32+AM32+AO32+AQ32+AS32+AU32+AW32+AY32+BA32+BC32 | BF32: =#REF!+L32+N32+P32+R32+T32+V32+X32+Z32+AB32+AD32+AF32+AH32+AJ32+AL32+AN32+AP32+AR32+AT32+AV32+AX32 | BG32: =BE32-BF32
A33: Возврат ВФП | B33: Расход | BE33: =K33+M33+O33+Q33+S33+U33+W33+Y33+AA33+AC33+AE33+AG33+AI33+AK33+AM33+AO33+AQ33+AS33+AU33+AW33+AY33+BA33+BC33 | BF33: =#REF!+L33+N33+P33+R33+T33+V33+X33+Z33+AB33+AD33+AF33+AH33+AJ33+AL33+AN33+AP33+AR33+AT33+AV33+AX33 | BG33: =BE33-BF33
A34: Представительские расходы | B34: Расход | BE34: =K34+M34+O34+Q34+S34+U34+W34+Y34+AA34+AC34+AE34+AG34+AI34+AK34+AM34+AO34+AQ34+AS34+AU34+AW34+AY34+BA34+BC34 | BF34: =#REF!+L34+N34+P34+R34+T34+V34+X34+Z34+AB34+AD34+AF34+AH34+AJ34+AL34+AN34+AP34+AR34+AT34+AV34+AX34 | BG34: =BE34-BF34
A35: Аренда помещений | B35: Расход | W35: -6655000 | BE35: =K35+M35+O35+Q35+S35+U35+W35+Y35+AA35+AC35+AE35+AG35+AI35+AK35+AM35+AO35+AQ35+AS35+AU35+AW35+AY35+BA35+BC35 | BF35: =#REF!+L35+N35+P35+R35+T35+V35+X35+Z35+AB35+AD35+AF35+AH35+AJ35+AL35+AN35+AP35+AR35+AT35+AV35+AX35 | BG35: =BE35-BF35
A36: Газ | B36: Расход | AO36: -630000 | AY36: -630000 | BE36: =K36+M36+O36+Q36+S36+U36+W36+Y36+AA36+AC36+AE36+AG36+AI36+AK36+AM36+AO36+AQ36+AS36+AU36+AW36+AY36+BA36+BC36 | BF36: =#REF!+L36+N36+P36+R36+T36+V36+X36+Z36+AB36+AD36+AF36+AH36+AJ36+AL36+AN36+AP36+AR36+AT36+AV36+AX36 | BG36: =BE36-BF36
A37: Маркетинг | B37: Расход | BE37: =K37+M37+O37+Q37+S37+U37+W37+Y37+AA37+AC37+AE37+AG37+AI37+AK37+AM37+AO37+AQ37+AS37+AU37+AW37+AY37+BA37+BC37 | BF37: =#REF!+L37+N37+P37+R37+T37+V37+X37+Z37+AB37+AD37+AF37+AH37+AJ37+AL37+AN37+AP37+AR37+AT37+AV37+AX37 | BG37: =BE37-BF37
A38: Мусор | B38: Расход | AC38: -100000 | AK38: -642920 | BE38: =K38+M38+O38+Q38+S38+U38+W38+Y38+AA38+AC38+AE38+AG38+AI38+AK38+AM38+AO38+AQ38+AS38+AU38+AW38+AY38+BA38+BC38 | BF38: =#REF!+L38+N38+P38+R38+T38+V38+X38+Z38+AB38+AD38+AF38+AH38+AJ38+AL38+AN38+AP38+AR38+AT38+AV38+AX38 | BG38: =BE38-BF38
A39: Налоги и другие платежи в бюджет | B39: Расход | AC39: -8000000 | AE39: -6000000 | AQ39: -12000000 | BA39: -12000000 | BE39: =K39+M39+O39+Q39+S39+U39+W39+Y39+AA39+AC39+AE39+AG39+AI39+AK39+AM39+AO39+AQ39+AS39+AU39+AW39+AY39+BA39+BC39 | BF39: =#REF!+L39+N39+P39+R39+T39+V39+X39+Z39+AB39+AD39+AF39+AH39+AJ39+AL39+AN39+AP39+AR39+AT39+AV39+AX39 | BG39: =BE39-BF39
A40: Оплата труда | B40: Расход | Q40: -18500000 | AK40: -2030000 | BE40: =K40+M40+O40+Q40+S40+U40+W40+Y40+AA40+AC40+AE40+AG40+AI40+AK40+AM40+AO40+AQ40+AS40+AU40+AW40+AY40+BA40+BC40 | BF40: =#REF!+L40+N40+P40+R40+T40+V40+X40+Z40+AB40+AD40+AF40+AH40+AJ40+AL40+AN40+AP40+AR40+AT40+AV40+AX40 | BG40: =BE40-BF40
...

Sheet ОБУ ИЮНЬ
A1: Сатья расхода | B1: Безналичныйрасчёт | H1: Наличныйрасчёт | N1: Итого Расходы май
B2: МАЙ 2026 года | G2: Итого без.нал | H2: МАЙ 2026 года | M2: Итого нал
B3: 1 неделя | C3: 2 неделя | D3: 3 неделя | E3: 4 неделя | F3: 5 неделя | H3: 1 неделя | I3: 2 неделя | J3: 3 неделя | K3: 4 неделя | L3: 5 неделя
A4: IT-обслуживание,телефония,интернет | B4: 170577 | C4: 310400 | G4: =B4+C4+D4+E4+F4 | M4: =SUM(H4:L4) | N4: =G4+M4
A5: Авансы поставщикам | G5: =B5+C5+D5+E5+F5 | M5: =SUM(H5:L5) | N5: =G5+M5
A6: Административные расходы | B6: 550000 | D6: 550000 | G6: =B6+C6+D6+E6+F6 | J6: 690000 | K6: 350000 | M6: =SUM(H6:L6) | N6: =G6+M6
A7: Страховка сотрудников | E7: 427718 | G7: =B7+C7+D7+E7+F7 | M7: =SUM(H7:L7) | N7: =G7+M7
A8: Возврат ВФП | G8: =B8+C8+D8+E8+F8 | M8: =SUM(H8:L8) | N8: =G8+M8
A9: Представительские расходы | G9: =B9+C9+D9+E9+F9 | M9: =SUM(H9:L9) | N9: =G9+M9
A10: Аренда помещений | D10: 6050000 | G10: =B10+C10+D10+E10+F10 | M10: =SUM(H10:L10) | N10: =G10+M10
A11: Газ | G11: =B11+C11+D11+E11+F11 | H11: 90000 | I11: 90000 | J11: 90000 | K11: 90000 | L11: 90000 | M11: =SUM(H11:L11) | N11: =G11+M11
A12: Маркетинг | G12: =B12+C12+D12+E12+F12 | M12: =SUM(H12:L12) | N12: =G12+M12
A13: Мусор | D13: 750000 | G13: =B13+C13+D13+E13+F13 | M13: =SUM(H13:L13) | N13: =G13+M13
A14: Налоги и другие платежи в бюджет (ЗАРПЛАТНЫЕ) | G14: =B14+C14+D14+E14+F14 | M14: =SUM(H14:L14) | N14: =G14+M14
A15: Налоги и другие платежи в бюджет (НДС) | G15: =B15+C15+D15+E15+F15 | M15: =SUM(H15:L15) | N15: =G15+M15
A16: Оплата труда (пятница-уволенные) (четверг-лагманщики) каждую неделю | G16: =B16+C16+D16+E16+F16 | H16: 2400000 | I16: 3000000 | J16: 2400000 | K16: 2400000 | L16: 2400000 | M16: =SUM(H16:L16) | N16: =G16+M16
A17: Оплата труда | C17: 16000000 | E17: 20000000 | G17: =B17+C17+D17+E17+F17 | I17: 20000000 | J17: 20000000 | K17: 20000000 | L17: 20000000 | M17: =SUM(H17:L17) | N17: =G17+M17
A18: Охрана | G18: =B18+C18+D18+E18+F18 | M18: =SUM(H18:L18) | N18: =G18+M18
A19: Платежи поставщикам Прочее | C19: 950000 | D19: 172450 | G19: =B19+C19+D19+E19+F19 | M19: =SUM(H19:L19) | N19: =G19+M19
A20: Производственные расходы | G20: =B20+C20+D20+E20+F20 | H20: 100000 | I20: 100000 | J20: 100000 | K20: 100000 | L20: 100000 | M20: =SUM(H20:L20) | N20: =G20+M20
A21: Инвентарь | G21: =B21+C21+D21+E21+F21 | M21: =SUM(H21:L21) | N21: =G21+M21
A22: Униформа | G22: =B22+C22+D22+E22+F22 | M22: =SUM(H22:L22) | N22: =G22+M22
A23: Упаковка | G23: =B23+C23+D23+E23+F23 | M23: =SUM(H23:L23) | N23: =G23+M23
A24: Хоз.товары | G24: =B24+C24+D24+E24+F24 | M24: =SUM(H24:L24) | N24: =G24+M24
A25: Погашение кредита и %% | B25: 1749942 | E25: 4013564 | G25: =B25+C25+D25+E25+F25 | M25: =SUM(H25:L25) | N25: =G25+M25
A26: Расходы по реализации Разные(Логистика) | D26: 1500000 | F26: 2000000 | G26: =B26+C26+D26+E26+F26 | M26: =SUM(H26:L26) | N26: =G26+M26
A27: Ремонт помещений | B27: 500000 | C27: 500000 | D27: 500000 | E27: 500000 | G27: =B27+C27+D27+E27+F27 | M27: =SUM(H27:L27) | N27: =G27+M27
A28: Ремонт оборудования | B28: 1000000 | C28: 500000 | D28: 500000 | E28: 1000000 | G28: =B28+C28+D28+E28+F28 | M28: =SUM(H28:L28) | N28: =G28+M28
A29: Приобретение основных средств | G29: =B29+C29+D29+E29+F29 | M29: =SUM(H29:L29) | N29: =G29+M29
A30: Сырье Платежи поставщикам Стас | G30: =B30+C30+D30+E30+F30 | H30: 2 000 000 | I30: 2 000 000 | J30: 2 000 000 | K30: 2 000 000 | L30: 2 000 000 | M30: =SUM(H30:L30) | N30: =G30+M30
A31: Электроэнергия и комун расходы | E31: 9000000 | G31: =B31+C31+D31+E31+F31 | M31: =SUM(H31:L31) | N31: =G31+M31
A32: ИТОГО | B32: =SUM(B4:B31) | C32: =SUM(C4:C31) | D32: =SUM(D4:D31) | E32: =SUM(E4:E31) | F32: =SUM(F4:F31) | G32: =B32+C32+D32+E32+F32 | H32: =SUM(H4:H31) | I32: =SUM(I4:I31) | J32: =SUM(J4:J31) | K32: =SUM(K4:K31) | L32: =SUM(L4:L31) | M32: =SUM(M4:M31) | N32: =G32+M32

Sheet ДДС МЕСЯЦ МАЙ
K1: 46143 | M1: 46146 | O1: 46147 | Q1: 46148 | S1: 46149 | U1: 46150 | W1: 46153 | Y1: 46154 | AA1: 46155 | AC1: 46156 | AE1: 46157 | AG1: 46160 | AI1: 46161 | AK1: 46162 | AM1: 46163 | AO1: 46164 | AQ1: 46167 | AS1: 46168 | AU1: 46169 | AW1: 46170 | AY1: 46171
K2: пятница | M2: понедельник | O2: вторник | Q2: среда | S2: четверг | U2: пятница | W2: понедельник | Y2: вторник | AA2: среда | AC2: четверг | AE2: пятница | AG2: понедельник | AI2: вторник | AK2: среда | AM2: четверг | AO2: пятница | AQ2: понедельник | AS2: вторник | AU2: среда | AW2: четверг | AY2: пятница | BA2: прирост 18% к факту апреля
K3: 46143 | M3: 46146 | O3: 46147 | Q3: 46148 | S3: 46149 | U3: 46150 | W3: 46153 | Y3: 46154 | AA3: 46155 | AC3: 46156 | AE3: 46157 | AG3: 46160 | AI3: 46161 | AK3: 46162 | AM3: 46163 | AO3: 46164 | AQ3: 46167 | AS3: 46168 | AU3: 46169 | AW3: 46170 | AY3: 46171 | BA3: Итого план | BB3: Итого факт | BC3: Отклонение
C4: План | D4: Факт | E4: План | F4: Факт | G4: План | H4: Факт | I4: План | J4: Факт | K4: План | L4: Факт | M4: План | N4: Факт | O4: План | P4: Факт | Q4: План | R4: Факт | S4: План | T4: Факт | U4: План | V4: Факт | W4: План | X4: Факт | Y4: План | Z4: Факт | AA4: План | AB4: Факт | AC4: План | AD4: Факт | AE4: План | AF4: Факт | AG4: План | AH4: Факт | AI4: План | AJ4: Факт | AK4: План | AL4: Факт | AM4: План | AN4: Факт | AO4: План | AP4: Факт
A5: Остаток на начало по Банку | C5: 3140328 | D5: =C5 | E5: =C81 | F5: =D81 | G5: =E81 | H5: =3139916 | I5: =G81 | J5: =H81 | K5: 0 | L5: 0 | M5: =K81 | N5: =L81 | O5: =M81 | P5: =N81 | Q5: =O81 | R5: =P81 | S5: =Q81 | T5: =R81 | ... AZ5: =AX81 | BA5: =C5 | BB5: =BA5 | BC5: =BB5-BA5
A6: Остаток на начало по Кассе | C6: 917728 | D6: =C6 | E6: =C82 | F6: =D82 | G6: =E82 | H6: =F82+62744 | I6: =G82 | J6: =H82 | K6: 0 | L6: 0 | M6: =K82 | N6: =L82 | O6: =M82 | P6: =N82 | Q6: =O82 | R6: =P82 | S6: =Q82 | T6: =R82 | ... AZ6: =AX82 | BA6: =C6 | BB6: =BA6 | BC6: =BB6-BA6
A7: Прочие | B7: Приход | G7: 1000000 | M7: 1000000 | Q7: 1000000 | U7: 1000000 | W7: 1000000 | AA7: 1000000 | AE7: 1000000 | AG7: 1000000 | AK7: 1000000 | AO7: 1000000 | AQ7: 1000000 | AU7: 1000000 | AY7: 1000000 | BA7: =K7+M7+O7+Q7+S7+U7+W7+Y7+AA7+AC7+AE7+AG7+AI7+AK7+AM7+AO7+AQ7+AS7+AU7+AW7+AY7 | BB7: =L7+N7+P7+R7+T7+V7+X7+Z7+AB7+AD7+AF7+AH7+AJ7+AL7+AN7+AP7+AR7+AT7+AV7+AX7+AZ7 | BC7: =BA7-BB7
A8: Б1, Б2, Б5 | B8: Приход | K8: 1000000 | O8: 1000000 | Q8: 1000000 | S8: 1000000 | U8: 1000000 | Y8: 1000000 | AC8: 1000000 | AE8: 1000000 | AI8: 1000000 | AM8: 1000000 | AO8: 1000000 | AS8: 1000000 | AU8: 1000000 | AW8: 1000000 | BA8: =K8+M8+O8+Q8+S8+U8+W8+Y8+AA8+AC8+AE8+AG8+AI8+AK8+AM8+AO8+AQ8+AS8+AU8+AW8+AY8 | BB8: =L8+N8+P8+R8+T8+V8+X8+Z8+AB8+AD8+AF8+AH8+AJ8+AL8+AN8+AP8+AR8+AT8+AV8+AX8+AZ8 | BC8: =BA8-BB8
A9: Яндекс | B9: Приход | I9: 6000000 | O9: 6000000 | S9: 10000000 | Y9: 6000000 | AC9: 10000000 | AI9: 6000000 | AM9: 10000000 | AS9: 9000000 | AW9: 10000000 | BA9: =K9+M9+O9+Q9+S9+U9+W9+Y9+AA9+AC9+AE9+AG9+AI9+AK9+AM9+AO9+AQ9+AS9+AU9+AW9+AY9 | BB9: =L9+N9+P9+R9+T9+V9+X9+Z9+AB9+AD9+AF9+AH9+AJ9+AL9+AN9+AP9+AR9+AT9+AV9+AX9+AZ9 | BC9: =BA9-BB9
